Workbook
Name __xlnm.Print_Area_37: "#REF!"

Sheet Tim
F1: 2ª FEIRA | AY1: 3ª FEIRA | CQ1: 4ª FEIRA | EL1: 5ª FEIRA | GD1: 6ª FEIRA | HV1: SÁBADO | JN1: DOMINGO
F2: IT | G2: SP | M2: AF | P2: PT | U2: TR | Y2: AD | AB2: VG | AC2: NT | AO2: AI | AP2: CF | AQ2: TRB | AT2: AG | AY2: IT | AZ2: SP | BF2: AF | BI2: PT | BN2: TR | BQ2: AD | BT2: VG | BU2: NT | CG2: AI | CH2: CF | CI2: TRB | CL2: AG | CQ2: IT | CR2: SP | CX2: AF | DA2: PT | DF2: TR | DI2: AD | DO2: VG | DP2: NT | EB2: AI | EC2: CF | ED2: TRB | EG2: AG | EL2: IT | EM2: SP | ES2: AF | EV2: PT | FA2: TR | FD2: AD | FG2: VG | FH2: NT | FT2: AI | FU2: CF | FV2: TRB | FY2: AG | GD2: IT | GE2: SP | GK2: AF | GN2: PT | GS2: TR | GV2: AD | GY2: VG | GZ2: NT | HL2: AI | HM2: CF | HN2: TRB | HQ2: AG | HV2: IT | HW2: SP | IC2: AF | IF2: PT | IK2: TR | IN2: AD | IQ2: VG | IR2: NT | JD2: AI | JE2: CF | JF2: TRB | JI2: AG | JN2: IT | JO2: SP | JU2: AF | JX2: PT | KC2: TR | KF2: AD | KI2: VG | KJ2: NT | KV2: AI | KW2: CF | KX2: TRB | LA2: AG
AC4: 1 | AD4: 2 | AE4: 3 | AF4: 4 | AG4: 5 | AH4: 6 | AI4: 7 | AJ4: 8 | AK4: 9 | AL4: 10 | AM4: 11 | AN4: 12 | AT4: E1 | AU4: E2 | AV4: E3 | AW4: RPM | AX4: PS | BU4: 1 | BV4: 2 | BW4: 3 | BX4: 4 | BY4: 5 | BZ4: 6 | CA4: 7 | CB4: 8 | CC4: 9 | CD4: 10 | CE4: 11 | CF4: 12 | CL4: E1 | CM4: E2 | CN4: E3 | CO4: RPM | CP4: PS | DP4: 1 | DQ4: 2 | DR4: 3 | DS4: 4 | DT4: 5 | DU4: 6 | DV4: 7 | DW4: 8 | DX4: 9 | DY4: 10 | DZ4: 11 | EA4: 12 | EG4: E1 | EH4: E2 | EI4: E3 | EJ4: RPM | EK4: PS | FH4: 1 | FI4: 2 | FJ4: 3 | FK4: 4 | FL4: 5 | FM4: 6 | FN4: 7 | FO4: 8 | FP4: 9 | FQ4: 10 | FR4: 11 | FS4: 12 | FY4: E1 | FZ4: E2 | GA4: E3 | GB4: RPM | GC4: PS | GZ4: 1 | HA4: 2 | HB4: 3 | HC4: 4 | HD4: 5 | HE4: 6 | HF4: 7 | HG4: 8 | HH4: 9 | HI4: 10 | HJ4: 11 | HK4: 12 | HQ4: E1 | HR4: E2 | HS4: E3 | HT4: RPM | HU4: PS | IR4: 1 | IS4: 2 | IT4: 3 | IU4: 4 | IV4: 5 | IW4: 6 | IX4: 7 | IY4: 8 | IZ4: 9 | JA4: 10 | JB4: 11 | JC4: 12 | JI4: E1 | JJ4: E2 | JK4: E3 | JL4: RPM | JM4: PS | KJ4: 1 | KK4: 2 | KL4: 3 | KM4: 4 | KN4: 5 | KO4: 6 | KP4: 7 | KQ4: 8 | KR4: 9 | KS4: 10 | KT4: 11 | KU4: 12 | LA4: E1 | LB4: E2 | LC4: E3 | LD4: RPM | LE4: PS
E5: 0.25
E6: 0.26041667
B7: 0.25 | C7: 0.25 | D7: 0.25 | E7: 0.27083333 | F7: RF | AY7: RF | CQ7: LA | DO7: RG | EL7: MS | GD7: CR | LF7: 0.29166667
B8: 0.25 | C8: 0.25 | D8: 0.25 | E8: 0.28125 | F8: RF | AY8: RF | CQ8: LA | DO8: RG | EL8: MS | GD8: CR | LF8: 0.30208333
B9: 0.25 | C9: 0.25 | D9: 0.25 | E9: 0.29166667 | F9: RF | AU9: HA | AY9: RF | CL9: LTS | CO9: RIM | CQ9: LA | DA9: LF | DO9: RG | EH9: HA | EL9: MS | FY9: LF | GA9: CR | GD9: CR | HT9: RIM | LF9: 0.3125
B10: 0.25 | C10: 0.25 | D10: 0.25 | E10: 0.30208333 | F10: RF | AU10: HA | AY10: RF | CL10: LTS | CO10: RIM | CQ10: LA | DA10: LF | DO10: RG | EH10: HA | EL10: MS | FY10: LF | GA10: CR | GD10: CR | HT10: RIM | LF10: 0.32291667
B11: 0.25 | C11: 0.25 | D11: 0.25 | E11: 0.3125 | F11: RF | AB11: RG | AU11: HA | AY11: RF | CL11: LTS | CO11: RIM | CQ11: LA | DA11: LF | DO11: RG | EH11: HA | EL11: MS | FY11: LF | GA11: CR | GD11: MS | GN11: CR | HT11: RIM | LF11: 0.33333333
B12: 0.25 | C12: 0.25 | D12: 0.25 | E12: 0.32291667 | F12: RF | AB12: RG | AU12: HA | AY12: CR | BN12: RF | CL12: LTS | CO12: RIM | CQ12: LA | DA12: LF | DO12: RG | EH12: HA | EL12: MS | FY12: LF | GA12: CR | GD12: MS | GN12: CR | HT12: RIM | LF12: 0.34375
B13: 0.25 | C13: 0.25 | D13: 0.25 | E13: 0.33333333 | F13: RF | AB13: RG | AV13: HA | AY13: CR | CP13: RF | CQ13: LA | DA13: LF | EG13: HA | EK13: RG | EL13: MS | FA13: LF | GC13: CR | GD13: CR | GM13: MS | HV13: RF | LF13: 0.35416667
B14: 0.25 | C14: 0.25 | D14: 0.25 | E14: 0.34375 | F14: RF | AB14: RG | AV14: HA | AY14: CR | CP14: RF | CQ14: LA | DA14: LF | EG14: HA | EK14: RG | EL14: LF | ET14: MS | GC14: CR | GD14: CR | GM14: MS | HV14: RF | LF14: 0.36458333
B15: 0.25 | C15: 0.25 | D15: 0.25 | E15: 0.35416667 | F15: RF | AB15: RG | AV15: HA | AY15: CR | CP15: RF | CQ15: LA | DF15: LF | EG15: HA | EK15: RG | EL15: LF | ET15: MS | GC15: CR | GD15: MS | GN15: CR | HV15: RF | LF15: 0.375
B16: 0.25 | C16: 0.25 | D16: 0.25 | E16: 0.36458333 | F16: RF | AB16: RG | AV16: HA | AY16: CR | CP16: RF | CQ16: LA | DF16: LF | EG16: HA | EK16: RG | EL16: LF | FD16: MS | GC16: CR | GD16: MS | GN16: CR | GZ16: JR | HA16: MAF | HV16: RF | LF16: 0.38541667
B17: 0.25 | C17: 0.25 | D17: 0.25 | E17: 0.375 | F17: RF | U17: HA | AC17: RG | AD17: LT | AV17: LTS | AY17: RF | CM17: CR | CQ17: LA | DF17: RG | DG17: HA | EG17: LF | EL17: CR | FZ17: LF | GB17: MS | GD17: MS | GN17: CR | GZ17: JR | HA17: MAF | HR17: LF | HV17: RF | JN17: RF | LF17: 0.39583333
B18: 0.25 | C18: 0.25 | D18: 0.25 | E18: 0.38541667 | F18: HA | Y18: RF | AC18: RG | AD18: LT | AV18: LTS | AY18: RF | CM18: CR | CQ18: LA | CR18: HA | DF18: RG | EG18: LF | EL18: CR | FZ18: LF | GB18: MS | GD18: MS | GN18: CR | GZ18: JR | HA18: MAF | HR18: LF | HV18: RF | JK18: GZ | JM18: LT | JN18: RF | LC18: RIM | LE18: LT | LF18: 0.40625
B19: 0.25 | C19: 0.25 | D19: 0.25 | E19: 0.39583333 | F19: HA | Y19: RF | AC19: RG | AD19: LT | AV19: LTS | AY19: RF | BU19: RG | CM19: CR | CQ19: HA | CR19: LA | DP19: RG | DQ19: CR | DR19: EDU | DS19: AD | DT19: RME | EG19: LF | EL19: CR | FZ19: LF | GB19: MS | GD19: MS | GN19: CR | GZ19: JR | HA19: MAF | HR19: LF | HV19: RF | JK19: GZ | JM19: LT | JN19: RF | LC19: RIM | LE19: LT | LF19: 0.41666667
B20: 0.25 | C20: 0.25 | D20: 0.25 | E20: 0.40625 | F20: HA | Y20: RF | AC20: RG | AD20: LT | AV20: LTS | AY20: RF | BU20: RG | CM20: CR | CQ20: HA | DF20: LA | DP20: RG | DQ20: CR | DR20: EDU | DS20: AD | DT20: RME | EG20: LF | EL20: CR | FH20: RG | FI20: EDU | FJ20: AD | FK20: AT | FZ20: LF | GB20: MS | GD20: MS | GN20: CR | GZ20: JR | HA20: MAF | HR20: LF | HV20: RF | JK20: GZ | JM20: LT | JN20: RF | LC20: RIM | LE20: LT | LF20: 0.42708333
B21: 0.25 | C21: 0.25 | D21: 0.25 | E21: 0.41666667 | F21: HA | Y21: RF | AC21: RG | AD21: LT | AO21: HA' | AU21: MRS | AY21: RF | BN21: CR | BQ21: LF | BU21: RG | CG21: RF' | CO21: CS | CQ21: HA | DF21: LF | DP21: RG | DQ21: CR | DR21: EDU | DS21: AD | DT21: RME | EH21: LA | EL21: CR | FA21: MS | FB21: LF | FH21: RG | FI21: EDU | FJ21: AD | FK21: AT | GD21: CR | GE21: MS | GV21: LF | GZ21: JR | HA21: MAF | HL21: MS' | HV21: RF | IS21: EDU | IT21: LT | JI21: LTS | JK21: GZ | JM21: LT | JN21: RF | KJ21: LT | LC21: RIM | LE21: LT | LF21: 0.4375
B22: 0.25 | C22: 0.25 | D22: 0.25 | E22: 0.42708333 | F22: HA | U22: RF | AC22: RG | AD22: LT | AU22: MRS | AY22: RF | BN22: CR | BQ22: LF | BT22: RG | CO22: CS | CQ22: HA | DB22: LF | DP22: RG | DQ22: CR | DR22: EDU | DS22: AD | DT22: RME | EH22: LA | EL22: MS | FA22: CR | FH22: RG | FI22: EDU | FJ22: AD | FK22: AT | GD22: CR | GT22: MS | GV22: LF | HU22: RG | HV22: RF | IS22: EDU | IT22: LT | JI22: LTS | JK22: GZ | JN22: RF | KJ22: LT | LD22: RIM | LF22: 0.44791667
B23: 0.25 | C23: 0.25 | D23: 0.25 | E23: 0.4375 | F23: HA | AT23: RF | AU23: MRS | AX23: RG | AY23: RF | BT23: RG | CN23: CR | CO23: CS | CP23: LF | CQ23: HA | DB23: LF | DP23: RG | DQ23: CR | DR23: EDU | DS23: AD | DT23: RME | EI23: MR | EL23: MS | FH23: RG | FI23: EDU | FJ23: AD | FK23: AT | FZ23: CR | GD23: HA | GM23: MS | GN23: CR | HR23: LF | HU23: RG | HV23: RF | IS23: EDU | IT23: LT | JI23: LTS | JJ23: AC | JK23: GZ | JN23: RF | KJ23: LT | LB23: LTS | LD23: RIM | LF23: 0.45833333
B24: 0.25 | C24: 0.25 | D24: 0.25 | E24: 0.44791667 | F24: HA | AT24: RF | AU24: MRS | AX24: RG | AY24: RF | AZ24: LA | BT24: RG | CN24: CR | CO24: CS | CP24: LF | CQ24: LF | CR24: HA | DP24: RG | DQ24: CR | DR24: EDU | DS24: AD | DT24: RME | EI24: MR | EL24: MS | ET24: LA | FH24: RG | FI24: EDU | FJ24: AD | FK24: AT | FZ24: CR | GD24: HA | GM24: MS | GN24: CR | HR24: LF | HU24: RG | HV24: RF | IS24: EDU | IT24: LT | JI24: LTS | JJ24: AC | JK24: GZ | JN24: RF | KJ24: LT | KK24: JR | LB24: LTS | LD24: RIM | LF24: 0.46875
B25: 0.25 | C25: 0.25 | D25: 0.25 | E25: 0.45833333 | F25: HA | P25: CR | U25: RF | AX25: RG | AY25: RF | AZ25: LA | BT25: RG | CN25: CR | CP25: LF | CQ25: LF | DB25: CR | DF25: HA | DI25: RG | DT25: RME | EI25: MR | EL25: MS | ET25: LA | FH25: RG | FI25: EDU | FJ25: AD | FK25: AT | FZ25: CR | GD25: RF | GL25: HA | GM25: MS | GN25: CR | HR25: LF | HU25: RG | HV25: LA | IF25: RF | IS25: EDU | IT25: LT | JJ25: AC | JK25: GZ | JN25: RF | KJ25: LT | KK25: JR | LB25: LTS | LD25: RIM | LF25: 0.47916667
B26: 0.25 | C26: 0.25 | D26: 0.25 | E26: 0.46875 | F26: RF | P26: CR | U26: HA | AX26: RG | AY26: LA | BN26: RF | BT26: RG | CN26: CR | CP26: LF | CQ26: LF | DB26: CR | DI26: RG | DT26: RME | EI26: MR | EK26: HA | EL26: MS | FA26: RG | FB26: LA | FZ26: CR | GD26: RF | GL26: HA | GM26: MS | GN26: CR | GZ26: RG | HR26: LF | HV26: LA | IF26: RF | IS26: EDU | IT26: LT | JJ26: AC | JN26: RF | KJ26: LT | KK26: JR | LB26: LTS | LF26: 0.48958333
B27: 0.25 | C27: 0.25 | D27: 0.25 | E27: 0.47916667 | F27: RF | P27: CR | AU27: HA | AX27: RG | AY27: HA | BF27: LA | BN27: LF | BO27: CR | BU27: RG | CN27: RF | CQ27: LF | DB27: CR | DI27: RG | DT27: RME | EH27: PE | EK27: HA | EL27: RG | EM27: MS | EW27: LF | FA27: CR | FZ27: LA | GD27: RF | GN27: CR | GP27: LF | GV27: HA | GZ27: RG | HR27: RV | HV27: LA | IF27: RF | IS27: EDU | IT27: LT | IU27: MF | JL27: AC | JN27: RF | KJ27: LT | KK27: JR | LA27: LTS | LB27: DIP | LD27: RIM | LF27: 0.5
B28: 0.25 | C28: 0.25 | D28: 0.25 | E28: 0.48958333 | F28: RF | P28: CR | AU28: HA | AX28: RG | AY28: HA | AZ28: LF | BF28: LA | BI28: CR | BU28: RG | CN28: RF | CQ28: LF | DB28: CR | DI28: RG | EH28: PE | EK28: HA | EL28: RG | EM28: CR | EW28: LF | FZ28: LA | GD28: RF | GN28: CR | GP28: LF | GV28: HA | GZ28: RG | HR28: RV | HV28: LA | IF28: RF | IS28: EDU | IT28: LT | IU28: MF | JL28: AC | JN28: RF | KJ28: LT | KK28: JR | LA28: LTS | LB28: DIP | LD28: RIM | LF28: 0.51041667
B29: 0.25 | C29: 0.25 | D29: 0.25 | E29: 0.5 | F29: RF | P29: CR | AU29: HA | AX29: RG | AY29: LA | BG29: HA | BH29: LF | BI29: CR | BU29: RG | CN29: RF | CQ29: LA | CX29: CR | DI29: RG | EH29: PE | EK29: HA | EL29: RG | EW29: LF | FE29: CR | FZ29: LA | GD29: RF | GN29: CR | GP29: LF | GV29: HA | GY29: RG | HR29: RV | HV29: RF | IF29: LA | IS29: EDU | IT29: LT | IU29: MF | JL29: AC | JN29: RF | KJ29: LT | KK29: JR | LA29: LTS | LB29: DIP | LD29: RIM | LF29: 0.52083333
B30: 0.25 | C30: 0.25 | D30: 0.25 | E30: 0.51041667 | F30: LF | P30: CR | AU30: HA | AX30: RG | AY30: LA | BG30: HA | BH30: LF | BI30: CR | CN30: RF | CQ30: LA | CR30: HA | CX30: CR | DI30: RG | EH30: PE | EL30: RG | EW30: LF | FE30: CR | FZ30: LA | GD30: RF | GN30: CR | GP30: LF | GV30: HA | GY30: RG | HR30: RV | HV30: RF | IF30: LA | IS30: EDU | IT30: LT | IU30: MF | JL30: AC | JN30: RF | LA30: LTS | LB30: DIP | LD30: RIM | LF30: 0.53125
B31: 0.25 | C31: 0.25 | D31: 0.25 | E31: 0.52083333 | F31: LF | U31: HA | V31: CR | AY31: LA | BI31: CR | BN31: LF | BO31: HA | CQ31: HA | DB31: CR | DH31: LA | EL31: LF | EM31: RG | FC31: LA | FE31: CR | GD31: RF | GN31: HA | GS31: MS | GT31: LF | GY31: RG | HV31: LA | IF31: RF | IS31: EDU | IT31: LT | IU31: MF | JN31: RF | LF31: 0.54166667
B32: 0.25 | C32: 0.25 | D32: 0.25 | E32: 0.53125 | F32: LF | AU32: CR | AW32: DP | AY32: LA | BI32: CR | CL32: JI | CM32: LF | CN32: HA | CQ32: HA | DB32: CR | EH32: LA | EJ32: MS | EL32: LF | FA32: HA | FE32: CR | FY32: LA | FZ32: MS | GD32: RF | GN32: HA | HR32: LF | HS32: MS | HV32: LA | IF32: RF | IS32: EDU | IT32: LT | IU32: MF | JN32: RF | LF32: 0.55208333
B33: 0.25 | C33: 0.25 | D33: 0.25 | E33: 0.54166667 | F33: LF | U33: MS | AU33: CR | AW33: DP | AY33: LA | BI33: CR | CL33: JI | CM33: LF | CN33: HA | CP33: MS | CQ33: HA | DB33: CR | EH33: LA | EJ33: MS | EL33: LF | FY33: LA | FZ33: MS | GC33: HA | GD33: LA | GK33: RF | GN33: HA | HR33: LF | HS33: MS | HV33: LA | LF33: 0.5625
B34: 0.25 | C34: 0.25 | D34: 0.25 | E34: 0.55208333 | F34: RF | U34: MS | Y34: LF | AU34: CR | AW34: DP | AY34: LA | BA34: CR | CL34: JI | CM34: LF | CN34: HA | CP34: MS | CQ34: HA | DB34: CR | EH34: LA | EJ34: MS | EL34: LF | FY34: LA | FZ34: MS | GC34: HA | GD34: LA | GK34: RF | GN34: HA | HR34: LF | HS34: MS | HV34: LA | LF34: 0.57291667
B35: 0.25 | C35: 0.25 | D35: 0.25 | E35: 0.5625 | F35: RF | U35: MS | Y35: LF | AB35: RG | AU35: CR | AW35: DP | AY35: LA | CL35: JI | CM35: LF | CN35: HA | CP35: MS | CQ35: LF | DO35: RG | EH35: LA | EJ35: MS | EL35: LF | FY35: LA | FZ35: MS | GC35: HA | GD35: LA | GK35: HA | GM35: RF | GN35: CR | HR35: LF | HS35: MS | HV35: LA | LF35: 0.58333333
B36: 0.25 | C36: 0.25 | D36: 0.25 | E36: 0.57291667 | F36: RF | U36: MS | W36: CR | Y36: LF | AB36: RG | AY36: LA | AZ36: RF' | BN36: HA | CP36: MS | CQ36: LF | DF36: LA | DG36: MS | DO36: RG | EL36: LF | FC36: MS | GC36: HA | GD36: LA | GK36: HA | GM36: RF | GN36: CR | GS36: LF | GT36: MS | HV36: LA | LF36: 0.59375
B37: 0.25 | C37: 0.25 | D37: 0.25 | E37: 0.58333333 | F37: HA | G37: RF | U37: MS | W37: CR | Y37: LF | AB37: RG | AY37: RF | BF37: LA | BO37: HA | BR37: MS | CQ37: LA | DD37: RP | DE37: RP | DM37: MS | DN37: LF | DO37: RG | EL37: MS | EM37: LF | FA37: HA | GD37: MS | GE37: HA | GN37: CR | GP37: LA | HV37: RF | JN37: RF | LF37: 0.60416667
B38: 0.25 | C38: 0.25 | D38: 0.25 | E38: 0.59375 | F38: HA | U38: MS | V38: RF | W38: CR | Y38: LF | AB38: RG | AY38: RF | BF38: LA | BO38: HA | BR38: MS | BT38: RG | CQ38: LA | DM38: MS | DN38: LF | DO38: RG | EL38: MS | FA38: HA | GD38: MS | GN38: CR | GP38: LA | HV38: RF | JN38: RF | LF38: 0.61458333
B39: 0.25 | C39: 0.25 | D39: 0.25 | E39: 0.60416667 | F39: HA | U39: MS | W39: CR | Z39: RG | AU39: LF | AX39: RF | AY39: LA | BO39: RF | BR39: MS | BT39: RG | CN39: CR | CP39: HA | CQ39: LA | DM39: MS | EK39: RG | EL39: MS | FD39: CR | FF39: RG | GA39: HA | GD39: MS | GN39: CR | HS39: LA | HU39: RG | HV39: RF | JN39: RF | LF39: 0.625
B40: 0.25 | C40: 0.25 | D40: 0.25 | E40: 0.61458333 | F40: HA | U40: MS | W40: CR | Z40: RG | AU40: LF | AX40: RF | AY40: LA | AZ40: LF | BO40: RF | BR40: MS | BT40: RG | CN40: CR | CP40: HA | CQ40: LA | DM40: MS | EK40: RG | EL40: MS | FD40: CR | FF40: RG | GA40: HA | GD40: MS | GN40: CR | HS40: LA | HU40: RG | HV40: RF | JN40: RF | LF40: 0.63541667
B41: 0.25 | C41: 0.25 | D41: 0.25 | E41: 0.625 | F41: HA | U41: MS | W41: CR | Z41: RG | AU41: LF | AX41: RF | AY41: LF | BF41: MS | BO41: RF | BT41: RG | CN41: CR | CP41: HA | CQ41: LA | CS41: HA | CX41: MS | DM41: CR | EK41: RG | EL41: LA | ET41: MS | FD41: CR | FF41: RG | GA41: HA | GD41: RF | GL41: MS | GN41: CR | GO41: LF | GP41: LA | HU41: RG | HV41: RF | IC41: LA | IS41: CAR | JN41: RF | LF41: 0.64583333
...

Sheet Max
B2: Local | C2: Dimensão (m²) | D2: 3m² | E2: 4m² | F2: ABS | G2: ALO | H2: CIR | I2: SQA | J2: TRX | K2: HDP | L2: EXT | M2: SPR | N2: BAT | O2: BBB | P2: BBL | Q2: BCB | R2: BPM | S2: CIR | T2: COR | U2: GAP | V2: DEF | W2: HID | X2: LOC | Y2: MST | Z2: PIL | AA2: PWJ | AB2: RPM | AC2: SHB | AD2: SOC | AE2: STP | AF2: TCH | AG2: YOG | AH2: ZUM
B3: Estúdio 1 | C3: 240 | D3: =C3/3 -> 80 | E3: =C3/4 -> 60 | F3: 60 | G3: 60 | L3: 30 | R3: 40 | AH3: 50
B4: Estúdio 2 | C4: 140 | D4: =C4/3 -> 46.666667 | E4: =C4/4 -> 35
B5: Estúdio 3 | C5: 50 | D5: =C5/3 -> 16.666667 | E5: =C5/4 -> 12.5
B6: Alta Performance | C6: 200 | D6: =C6/3 -> 66.666667 | E6: =C6/4 -> 50
B7: Estúdio RPM | C7: 100 | D7: =C7/3 -> 33.333333 | E7: =C7/4 -> 25 | AB7: 40
B8: Piscina | C8: =18*8 -> 144 | D8: =C8/3 -> 48 | E8: =C8/4 -> 36 | K8: 50
B9: Interacção | C9: 20 | D9: =C9/3 -> 6.6666667 | E9: =C9/4 -> 5 | F9: 15 | G9: 15 | H9: 15 | I9: 10 | J9: 10
B10: Outdoor | C10: - | E10: =SUM(E3:E9) -> 223.5 | F10: 15 | G10: 15 | H10: 15 | I10: 10 | J10: 10 | M10: 30

Sheet Map
A1: MAPA DE AULAS DE GRUPO - SOLINCA LARANJEIRAS
C2: SEGUNDA | E2: TERÇA | G2: QUARTA | I2: QUINTA | K2: SEXTA | M2: SÁBADO | O2: DOMINGO
C3: Est. 1 | Dur 55' | G3: Est. 1 | Dur 55' | I3: Est. 1 | Dur 55'
A4: 07h05 | C4: BODY PUMP | G4: BODY ATTACK | I4: BODY BALANCE
E5: Est. B | Dur 45' | K5: Est. B | Dur 55'
A6: 07h15 | E6: RPM | K6: RPM
K7: Est. 1 | Dur 45'
A8: 08h30 | K8: GINÁSTICA GL
C9: Est. 1 | Dur 55' | E9: Est. 1 | Dur 55' | G9: Est. 1 | Dur 30' | I9: Est. 1 | Dur 55' | K9: Est. 1 | Dur 55'
A10: 09h30 | C10: PILATES | E10: WELLTRAINING | G10: PILATES | I10: PILATES | K10: WELLTRAINING
G11: Est. B | Dur 55'
G12: RPM
G13: Est. 1 | Dur 30' | M13: Est. 1 | Dur 55' | O13: Est. B | Dur 55'
A14: 10h00 | G14: ALONGAMENTOS | M14: BODY PUMP | O14: SPINNING
M15: Est. 2 | Dur 45'
A16: 10h15 | M16: LOCAL
C17: Est. 1 | Dur 55´ | E17: Est. 1 | Dur 45' | G17: Est. 1 | Dur 55´ | I17: Est. 1 | Dur ´55 | K17: Est. 1 | Dur 55
A18: 10h30 | C18: LOCAL | E18: LOCAL | G18: LOCAL | I18: LOCAL | K18: LOCAL
C19: Piscina | Dur 45' | G19: Piscina | Dur 45' | K19: Piscina | Dur 45'
A20: 10h45 | C20: HIDRO | G20: HIDRO | K20: HIDRO
M21: Est. AP | Dur 55' | O21: Est. 1 | Dur 55'
A22: 11h00 | M22: CROSS | O22: LOCAL
M23: Est. 2 | Dur 45'
M24: ALONGAMENTOS
M25: Est. B | Dur 45'
A26: 11h10 | M26: RPM
M27: Est. 1 | Dur 55'
A28: 11h15 | M28: ZUMBA
C29: Est. 2 | Dur 45' | I29: Est. 1 | Dur 45' | O29: Piscina | Dur 45'
A30: 11h30 | C30: ALONGAMENTOS | I30: ALONGAMENTOS | O30: HIDRO
M31: Est. 2 | Dur 55' | O31: Est. 1 | Dur 55'
A32: 12h00 | M32: BODY COMBAT | O32: PILATES
M33: Est. 1 | Dur 45'
A34: 12h15 | M34: BODY STEP
C35: Est. 2 | Dur 45' | E35: Est. 1 | Dur 45' | G35: Est. 2 | Dur 45' | K35: Est. 1 | Dur 45' | M35: Piscina | Dur 45'
A36: 12h30 | C36: ZUMBA | E36: AERÓBICA | G36: LOCAL | K36: STEP COR. | M36: HIDRO
C37: Est. AP | Dur 55' | G37: Est. AP | Dur 55' | I37: Est. 2 | Dur 30' | K37: Est. AP | Dur 55'
A38: 12h45 | C38: CROSS | G38: CROSS | I38: 3B | K38: CROSS
C39: Est. 1 | Dur 55' | E39: Est. 2 | Dur 55' | G39: Est. 3 | Dur 55' | I39: Est. B | Dur 55'
A40: 13h00 | C40: AERO LOCAL | E40: BODY BALANCE | I40: RPM
...

Sheet Map Ins
A1: MAPA DE AULAS DE GRUPO - SOLINCA LARANJEIRAS
C2: SEGUNDA | E2: TERÇA | G2: QUARTA | I2: QUINTA | K2: SEXTA | M2: SÁBADO | O2: DOMINGO
C3: LUISA ZIGUE | G3: LUISA ZIGUE | I3: RITA CRISOSTOMO
A4: 07h05 | C4: BODY PUMP | G4: BODY ATTACK | I4: BODY BALANCE
E5: PEDRO MENDES | K5: PEDRO MENDES
A6: 07h15 | E6: RPM | K6: RPM
K7: JENIFER PIOVANI
A8: 08h30 | K8: GINÁSTICA GL
C9: SANDRA FONTES | E9: RITA MADEIRA | G9: RITA OLIVEIRA | I9: RITA OLIVEIRA | K9: RITA MADEIRA
A10: 09h30 | C10: PILATES | E10: WELLTRAINING | G10: PILATES | I10: PILATES | K10: WELLTRAINING
G11: GONÇALO RUIVO
G12: RPM
G13: RITA OLIVEIRA | M13: LUISA ZIGUE | O13: TULIO FONSECA
A14: 10h00 | G14: ALONGAMENTOS | M14: BODY PUMP | O14: SPINNING
M15: 360 FIT
A16: 10h15 | M16: LOCAL
C17: TULIO FONSECA | E17: JENIFER PIOVANI | G17: RITA MADEIRA | I17: RITA MADEIRA | K17: RITA MADEIRA
A18: 10h30 | C18: LOCAL | E18: LOCAL | G18: LOCAL | I18: LOCAL | K18: LOCAL
C19: JENIFER PIOVANI | G19: JENIFER PIOVANI | K19: JENIFER PIOVANI
A20: 10h45 | C20: HIDRO | G20: HIDRO | K20: HIDRO
M21: ANGELO ORLINDO | O21: TULIO FONSECA
A22: 11h00 | M22: CROSS TONIK | O22: LOCAL
M23: 360 FIT
M24: ALONGAMENTOS
M25: PEDRO MENDES
A26: 11h10 | M26: RPM
A28: 11h15 | M28: ZUMBA
C29: GONÇALO RUIVO | I29: RITA MADEIRA | O29: JOANA SANTOS
A30: 11h30 | C30: ALONGAMENTOS | I30: ALONGAMENTOS | O30: HIDRO
M31: LUISA ZIGUE | O31: ANABELA AFONSO
A32: 12h00 | M32: BODY COMBAT | O32: PILATES
M33: MÓNICA MARUM
A34: 12h15 | M34: BODY STEP
C35: WILLIAM | E35: JORGE COSTA | G35: TEODORO MESQUITA | K35: TEODORO MESQUITA | M35: RITA CRISOSTOMO
A36: 12h30 | C36: ZUMBA | E36: AERÓBICA | G36: LOCAL | K36: STEP COR. | M36: HIDRO
C37: ANGELO ORLINDO | G37: ANGELO ORLINDO | I37: RITA MADEIRA | K37: ANGELO ORLINDO
A38: 12h45 | C38: CROSS TONIK | G38: CROSS TONIK | I38: 3B | K38: CROSS TONIK
C39: PATRICIA CANARIO | E39: RITA CRISOSTOMO | I39: PEDRO MENDES
A40: 13h00 | C40: AERO LOCAL | E40: BODY BALANCE | I40: RPM
G41: CARLA FERRAZ | I41: GONÇALO RUIVO
...

Sheet Ins AG
D2: Interação | I2: Tribes | O2: Aulas
B3: To Be | D3: IT | E3: VG | F3: PT | G3: H | I3: SPR | J3: EXT | K3: FCL | L3: CTK | M3: Sum | O3: AEB | P3: AEL | Q3: ALO | R3: BAT | S3: BBB | T3: BBL | U3: BCB | V3: BPM | W3: BST | X3: BVV | Y3: BDC | Z3: CFC | AA3: KMG | AB3: GAP | AC3: GGL | AD3: WLT | AE3: HID | AF3: LOC | AG3: KIZ | AH3: PIL | AI3: PWJ | AJ3: RPM | AK3: SHB | AL3: SOC | AM3: SPN | AN3: STP | AO3: TBR | AP3: TRR | AQ3: YOG | AR3: ZUM | AS3: Sum | AT3: Tot
B4: 2ª feira | L4: 3 | M4: =SUM(I4:L4) -> 3 | P4: 1 | Q4: 1 | S4: 1 | T4: 1 | U4: 1 | V4: 1 | W4: 1 | AE4: 2 | AF4: 1 | AH4: 3 | AI4: 1 | AJ4: 2 | AR4: 1 | AS4: =SUM(O4:AR4) -> 17 | AT4: =AS4+M4 -> 20
B5: 3ª feira | K5: 1 | L5: 2 | M5: =SUM(I5:L5) -> 3 | O5: 1 | P5: 1 | R5: 1 | T5: 1 | V5: 1 | Z5: 1 | AB5: 1 | AD5: 1 | AF5: 1 | AJ5: 1 | AM5: 1 | AN5: 1 | AQ5: 1 | AS5: =SUM(O5:AR5) -> 13 | AT5: =AS5+M5 -> 16
B6: 4ª feira | L6: 3 | M6: =SUM(I6:L6) -> 3 | Q6: 1 | R6: 1 | Y6: 1 | AE6: 2 | AF6: 3 | AG6: 1 | AH6: 2 | AJ6: 1 | AM6: 1 | AN6: 1 | AO6: 1 | AQ6: 1 | AR6: 2 | AS6: =SUM(O6:AR6) -> 18 | AT6: =AS6+M6 -> 21
B7: 5ª feira | L7: 2 | M7: =SUM(I7:L7) -> 2 | Q7: 1 | S7: 1 | T7: 1 | V7: 2 | Y7: 1 | Z7: 1 | AA7: 1 | AF7: 2 | AH7: 2 | AI7: 1 | AJ7: 1 | AM7: 1 | AN7: 1 | AQ7: 1 | AS7: =SUM(O7:AR7) -> 17 | AT7: =AS7+M7 -> 19
B8: 6ª feira | K8: 1 | L8: 2 | M8: =SUM(I8:L8) -> 3 | R8: 1 | S8: 1 | Y8: 1 | AC8: 1 | AD8: 1 | AE8: 2 | AF8: 2 | AM8: 2 | AN8: 1 | AO8: 1 | AR8: 1 | AS8: =SUM(O8:AR8) -> 14 | AT8: =AS8+M8 -> 17
B9: Sábado | L9: 1 | M9: =SUM(I9:L9) -> 1 | Q9: 1 | U9: 1 | V9: 1 | W9: 1 | AE9: 1 | AF9: 2 | AH9: 1 | AM9: 1 | AR9: 1 | AS9: =SUM(O9:AR9) -> 10 | AT9: =AS9+M9 -> 11
B10: Domingo | M10: =SUM(I10:L10) -> 0 | AE10: 1 | AF10: 1 | AH10: 1 | AM10: 1 | AS10: =SUM(O10:AR10) -> 4 | AT10: =AS10+M10 -> 4
B11: Total | D11: =SUM(D4:D10) -> 0 | E11: =SUM(E4:E10) -> 0 | F11: =SUM(F4:F10) -> 0 | I11: =SUM(I4:I10) -> 0 | J11: =SUM(J4:J10) -> 0 | K11: =SUM(K4:K10) -> 2 | L11: =SUM(L4:L10) -> 13 | M11: =SUM(M4:M10) -> 15 | O11: =SUM(O4:O10) -> 1 | P11: =SUM(P4:P10) -> 2 | Q11: =SUM(Q4:Q10) -> 4 | R11: =SUM(R4:R10) -> 3 | S11: =SUM(S4:S10) -> 3 | T11: =SUM(T4:T10) -> 3 | U11: =SUM(U4:U10) -> 2 | V11: =SUM(V4:V10) -> 5 | ... AT11: =SUM(AT4:AT10) -> 108
B13: Nome | C13: Contato
B14: Rita Oliveira | F14: 1 | M14: =SUM(I14:L14) -> 0 | Q14: 1 | S14: 1 | T14: 1 | Y14: 1 | AF14: 1 | AH14: 1 | AQ14: 1 | AS14: =SUM(O14:AR14) -> 7 | AU14: FH Loures, tem CXWorkx
B15: Carla Ferraz | M15: =SUM(I15:L15) -> 0 | AQ15: 1 | AS15: =SUM(O15:AR15) -> 1 | AU15: Jazzy Benfica e Odivelas. Escola Yoga 5 Outubro
B16: Pedro Luis | L16: 1 | M16: =SUM(I16:L16) -> 1 | V16: 1 | AJ16: 1 | AQ16: 1 | AS16: =SUM(O16:AR16) -> 3 | AU16: Level CF. Fitness Hut
B17: Ana Fortes | C17: 912 645 230 | M17: =SUM(I17:L17) -> 0 | U17: 1 | AB17: 1 | AF17: 1 | AH17: 1 | AI17: 1 | AS17: =SUM(O17:AR17) -> 5
B18: Ana Rita Oliveira | C18: 963 754 046 | M18: =SUM(I18:L18) -> 0 | AS18: =SUM(O18:AR18) -> 0
B19: Anabela Afonso | C19: 960 350 760 | M19: =SUM(I19:L19) -> 0 | T19: 1 | AE19: 1 | AF19: 1 | AH19: 1 | AJ19: 1 | AS19: =SUM(O19:AR19) -> 5
B20: João Neves | D20: 1 | F20: 1 | M20: =SUM(I20:L20) -> 0 | V20: 1 | AE20: 1 | AF20: 1 | AS20: =SUM(O20:AR20) -> 3 | AU20: Ligado ao Carlos Santos
B21: André Dias | C21: 963 754 046 | M21: =SUM(I21:L21) -> 0 | AS21: =SUM(O21:AR21) -> 0
B22: André Silva | C22: 919 926 798 | D22: 1 | F22: 1 | G22: 50 | K22: 1 | M22: =SUM(I22:L22) -> 1 | AS22: =SUM(O22:AR22) -> 0
B23: Andreia Amaral | C23: 916 056 090 | D23: 1 | M23: =SUM(I23:L23) -> 0 | O23: 1 | Q23: 1 | AB23: 1 | AF23: 1 | AJ23: 1 | AN23: 1 | AS23: =SUM(O23:AR23) -> 6 | AU23: Não fez estágio profissional | AV23: Trabalha no Fitness Hut Benfica
B24: Angelo Orlindo | C24: 963 122 887 | M24: =SUM(I24:L24) -> 0 | AS24: =SUM(O24:AR24) -> 0
B25: Bruno Rebelo | C25: 968 870 666 | D25: 1 | F25: 1 | G25: 50 | M25: =SUM(I25:L25) -> 0 | AS25: =SUM(O25:AR25) -> 0
B26: Vasco Santos | M26: =SUM(I26:L26) -> 0 | O26: 1 | AM26: 1 | AN26: 1 | AS26: =SUM(O26:AR26) -> 3 | AU26: Não é de ginásios grandes -> What?
B27: Monica Marum | M27: =SUM(I27:L27) -> 0 | R27: 1 | T27: 1 | W27: 1 | AB27: 1 | AF27: 1 | AK27: 1 | AS27: =SUM(O27:AR27) -> 6 | AU27: Fitness Hut…
B28: Rui Paulino | L28: 1 | M28: =SUM(I28:L28) -> 1 | AM28: 1 | AS28: =SUM(O28:AR28) -> 1 | AU28: Crossfit
B29: Marco Rocha | G29: 10 | M29: =SUM(I29:L29) -> 0 | AS29: =SUM(O29:AR29) -> 0 | AU29: Professor numa escola privada no restelo.
B30: Leonor Camilo | C30: 918 868 839 | D30: 1 | F30: 1 | G30: 60 | L30: 1 | M30: =SUM(I30:L30) -> 1 | Z30: 1 | AS30: =SUM(O30:AR30) -> 1
B31: Sérgio Silva | C31: 933 421 296 | F31: 1 | G31: 5 | M31: =SUM(I31:L31) -> 0 | AS31: =SUM(O31:AR31) -> 0 | AU31: É professor de Educação Física | AV31: Tem PT's fora | AW31: Bruno ou Miguel
B32: Luisa Zigue | M32: =SUM(I32:L32) -> 0 | R32: 1 | U32: 1 | AJ32: 1 | AS32: =SUM(O32:AR32) -> 3 | AU32: Não é a atividade principal | AV32: Cedo de manhã, final do dia e Sábado
B33: Maria João Reis | M33: =SUM(I33:L33) -> 0 | Q33: 1 | AF33: 1 | AM33: 1 | AS33: =SUM(O33:AR33) -> 3
B34: Rita Crisóstomo | M34: =SUM(I34:L34) -> 0 | T34: 1 | Y34: 1 | AH34: 1 | AS34: =SUM(O34:AR34) -> 3 | AU34: Exclusivo, exceção de uma aula num colégio
B35: Rafaela Rede | G35: 4 | M35: =SUM(I35:L35) -> 0 | S35: 1 | AS35: =SUM(O35:AR35) -> 1 | AU35: Fitness Hut Amoreiras
B36: Noel Delgado | F36: 1 | G36: 15 | M36: =SUM(I36:L36) -> 0 | AC36: 1 | AM36: 1 | AS36: =SUM(O36:AR36) -> 2
B37: Patrícia Canário | C37: 963 018 933 | G37: 20 | M37: =SUM(I37:L37) -> 0 | O37: 1 | P37: 1 | AB37: 1 | AF37: 1 | AM37: 1 | AS37: =SUM(O37:AR37) -> 5
B38: Tulio Fonseca | M38: =SUM(I38:L38) -> 0 | AM38: 1 | AN38: 1 | AS38: =SUM(O38:AR38) -> 2 | AU38: IMFit
B39: Rita Madeira | D39: 1 | F39: 1 | G39: 30 | M39: =SUM(I39:L39) -> 0 | O39: 1 | S39: 1 | AF39: 1 | AH39: 1 | AN39: 1 | AO39: 1 | AS39: =SUM(O39:AR39) -> 6
B40: Luis Cortez | D40: 1 | F40: 1 | G40: 20 | M40: =SUM(I40:L40) -> 0 | AS40: =SUM(O40:AR40) -> 0
B41: José Carraca | C41: 931 142 010 | F41: 1 | G41: 5 | M41: =SUM(I41:L41) -> 0 | AS41: =SUM(O41:AR41) -> 0
B42: Luis Belo | C42: 933 333 615 | M42: =SUM(I42:L42) -> 0 | R42: 1 | V42: 1 | AS42: =SUM(O42:AR42) -> 2 | AU42: Trabalha para a Galp - assistência técnica Gás
...

Sheet Nsm
B1: NEEDSCOPE MODEL - TONIK
D2: SEGUNDA | F2: TERÇA | H2: QUARTA | J2: QUINTA | L2: SEXTA | N2: SÁBADO | P2: DOMINGO
A3: Early Morning
B4: 07h05 | D4: BODY PUMP | H4: BODY BALANCE
B6: 07h15 | F6: RPM | L6: SPINNING
B8: 08h00 | J8: HIDRO
B10: 08h30 | L10: GINÁSTICA GL
A11: Morning
B12: 09h00 | J12: ZUMBA
B14: 09h30 | D14: PILATES | F14: WELLTRAINING | H14: PILATES | J14: PILATES | L14: WELLTRAINING
H16: RPM
B18: 10h00 | H18: ALONGAMENTOS | N18: BODY PUMP | P18: SPINNING
B20: 10h15 | N20: LOCAL
B22: 10h30 | D22: LOCAL | H22: LOCAL | J22: LOCAL | L22: LOCAL
B24: 10h45 | D24: HIDRO | H24: HIDRO | L24: HIDRO
B26: 11h00 | N26: ZUMBA | P26: LOCAL
N28: CROSS TONIK
N30: ALONGAMENTOS
B32: 11h10 | N32: RPM
B34: 11h30 | J34: ALONGAMENTOS | P34: HIDRO
A35: Lunch
B36: 12h00 | N36: BODY COMBAT | P36: PILATES
B38: 12h30 | D38: ZUMBA | F38: AERÓBICA | H38: LOCAL | L38: STEP COR. | N38: HIDRO
B40: 12h45 | D40: CROSS TONIK | H40: CROSS TONIK | J40: 3B | L40: CROSS TONIK
B42: 13h00 | D42: AERO LOCAL | F42: BODY BALANCE | H42: TONIK BURN | J42: SPINNING
D44: RPM
B46: 13h15 | D46: PILATES | F46: CIR. FUNCIONAL | H46: ZUMBA | J46: CIR. FUNCIONAL | L46: TONIK BURN
F48: STEP COR. | J48: BARRA DE CHÃO
A49: Peak
B50: 18h15 | D50: POWER JUMP | F50: AERO LOCAL | L50: BODY ATTACK
B52: 18h20 | H52: LOCAL
B54: 18h30 | D54: IN. CROSS TONIK | J54: LOCAL | L54: LOCAL
D56: PILATES
B58: 19h00 | F58: SPINNING | H58: CROSS TONIK | J58: SPINNING | L58: BARRA DE CHÃO
F60: YOGA | J60: CROSS TONIK | L60: CROSS TONIK
F62: CROSS TONIK | J62: YOGA
F64: BODY ATTACK
B66: 19h15 | D66: BODY STEP | F66: GAP | H66: ZUMBA | J66: BODY PUMP | L66: ZUMBA
D68: 3B | H68: PILATES | J68: STEP COR. | L68: RPM
D70: RPM | H70: SPINNING
...

Sheet CC
A1: PK | B1: OP | C1: SO | D1: MAPA DE AULAS DE GRUPO - TONIK | P1: PK | Q1: OP | R1: SO
A2: 11.59 | B2: 9.49 | C2: 4.99 | F2: SEGUNDA | H2: TERÇA | J2: QUARTA | L2: QUINTA | N2: SEXTA | P2: 11.59 | Q2: 9.49 | R2: 4.99 | S2: SÁBADO | U2: DOMINGO
F3: Est. 1 | Dur 55' | J3: Est. 1 | Dur 55' | L3: Est. 1 | Dur 55'
D4: 07h05 | F4: BODY PUMP | J4: BODY ATTACK | L4: BODY BALANCE
H5: Est. B | Dur 45' | N5: Est. B | Dur 55'
D6: 07h15 | H6: RPM | N6: RPM
N7: Est. 1 | Dur 45'
D8: 08h30 | N8: GINÁSTICA GL
F9: Est. 1 | Dur 55' | H9: Est. 1 | Dur 55' | J9: Est. 1 | Dur 30' | L9: Est. 1 | Dur 55' | N9: Est. 1 | Dur 55'
D10: 09h30 | F10: PILATES | H10: WELLTRAINING | J10: PILATES | L10: PILATES | N10: WELLTRAINING
J11: Est. B | Dur 55'
J12: RPM
J13: Est. 1 | Dur 30' | S13: Est. 1 | Dur 55' | U13: Est. B | Dur 55'
D14: 10h00 | J14: ALONGAMENTOS | S14: BODY PUMP | U14: SPINNING
S15: Est. 2 | Dur 45'
D16: 10h15 | S16: LOCAL
F17: Est. 1 | Dur 55´ | H17: Est. 1 | Dur 45' | J17: Est. 1 | Dur 55´ | L17: Est. 1 | Dur ´55 | N17: Est. 1 | Dur 55
D18: 10h30 | F18: LOCAL | H18: LOCAL | J18: LOCAL | L18: LOCAL | N18: LOCAL
F19: Piscina | Dur 45' | J19: Piscina | Dur 45' | N19: Piscina | Dur 45'
D20: 10h45 | F20: HIDRO | J20: HIDRO | N20: HIDRO
S21: Est. AP | Dur 55' | U21: Est. 1 | Dur 55'
D22: 11h00 | S22: CROSS | U22: LOCAL
S23: Est. 2 | Dur 45'
S24: ALONGAMENTOS
S25: Est. B | Dur 45'
D26: 11h10 | S26: RPM
S27: Est. 1 | Dur 55'
D28: 11h15 | S28: ZUMBA
F29: Est. 2 | Dur 45' | L29: Est. 1 | Dur 45' | U29: Piscina | Dur 45'
D30: 11h30 | F30: ALONGAMENTOS | L30: ALONGAMENTOS | U30: HIDRO
S31: Est. 2 | Dur 55' | U31: Est. 1 | Dur 55'
D32: 12h00 | S32: BODY COMBAT | U32: PILATES
S33: Est. 1 | Dur 45'
D34: 12h15 | S34: BODY STEP
F35: Est. 2 | Dur 45' | H35: Est. 1 | Dur 45' | J35: Est. 2 | Dur 45' | N35: Est. 1 | Dur 45' | S35: Piscina | Dur 45'
D36: 12h30 | F36: ZUMBA | H36: AERÓBICA | J36: LOCAL | N36: STEP COR. | S36: HIDRO
F37: Est. AP | Dur 55' | J37: Est. AP | Dur 55' | L37: Est. 2 | Dur 30' | N37: Est. AP | Dur 55'
D38: 12h45 | F38: CROSS | J38: CROSS | L38: 3B | N38: CROSS
F39: Est. 1 | Dur 55' | H39: Est. 2 | Dur 55' | J39: Est. 3 | Dur 55' | L39: Est. B | Dur 55'
D40: 13h00 | F40: AERO LOCAL | H40: BODY BALANCE | L40: RPM
...

Sheet H2O
A1: MAPA DE AULAS DE GRUPO - Solinca Laranjeiras - Piscina
C2: SEGUNDA | E2: TERÇA | G2: QUARTA | I2: QUINTA | K2: SEXTA | M2: SÁBADO | O2: DOMINGO
A4: 07h00 | C4: LIVRE | E4: LIVRE | G4: LIVRE | I4: LIVRE | K4: LIVRE
A6: 07h30 | C6: LIVRE | E6: LIVRE | G6: LIVRE | I6: LIVRE | K6: LIVRE
I7: Dur - 45'
A8: 08h00 | C8: LIVRE | E8: LIVRE | G8: LIVRE | K8: LIVRE
A10: 08h30 | C10: LIVRE | E10: LIVRE | G10: LIVRE | K10: LIVRE
A12: 09h00 | C12: CONDICIONADO | E12: LIVRE | G12: LIVRE | I12: LIVRE | K12: CONDICIONADO | M12: OCUPADO | O12: LIVRE
A14: 09h30 | C14: CONDICIONADO | E14: CONDICIONADO | G14: CONDICIONADO | I14: CONDICIONADO | K14: CONDICIONADO | M14: OCUPADO | O14: LIVRE
A16: 10h00 | C16: CONDICIONADO | E16: CONDICIONADO | G16: CONDICIONADO | I16: CONDICIONADO | K16: CONDICIONADO | M16: OCUPADO | O16: CONDICIONADO
G17: Dur - 45' | K17: Dur - 45'
A18: 10h30 | E18: CONDICIONADO | I18: CONDICIONADO | M18: OCUPADO | O18: CONDICIONADO
A20: 11h00 | E20: CONDICIONADO | I20: LIVRE | M20: OCUPADO | O20: CONDICIONADO
O21: Dur - 45'
A22: 11h30 | C22: CONDICIONADO | E22: CONDICIONADO | G22: CONDICIONADO | I22: CONDICIONADO | K22: CONDICIONADO | M22: OCUPADO
A24: 12h00 | C24: CONDICIONADO | E24: CONDICIONADO | G24: CONDICIONADO | I24: CONDICIONADO | K24: CONDICIONADO | M24: OCUPADO
A26: 12h30 | C26: CONDICIONADO | E26: CONDICIONADO | G26: CONDICIONADO | I26: CONDICIONADO | K26: CONDICIONADO | O26: LIVRE
A28: 13h00 | C28: CONDICIONADO | E28: CONDICIONADO | G28: CONDICIONADO | I28: CONDICIONADO | K28: CONDICIONADO | O28: LIVRE
A30: 13h30 | C30: CONDICIONADO | E30: CONDICIONADO | G30: CONDICIONADO | I30: CONDICIONADO | K30: CONDICIONADO | M30: LIVRE | O30: LIVRE
A32: 14h00 | C32: CONDICIONADO | E32: CONDICIONADO | G32: CONDICIONADO | I32: CONDICIONADO | K32: CONDICIONADO | M32: LIVRE | O32: LIVRE
A34: 14h30 | C34: CONDICIONADO | E34: CONDICIONADO | G34: CONDICIONADO | I34: CONDICIONADO | K34: CONDICIONADO | M34: LIVRE | O34: LIVRE
A36: 15h00 | C36: CONDICIONADO | E36: CONDICIONADO | G36: CONDICIONADO | I36: CONDICIONADO | K36: CONDICIONADO | M36: LIVRE | O36: LIVRE
A38: 15h30 | C38: CONDICIONADO | E38: CONDICIONADO | G38: CONDICIONADO | I38: CONDICIONADO | K38: CONDICIONADO | M38: LIVRE | O38: LIVRE
A40: 16h00 | C40: LIVRE | E40: LIVRE | G40: LIVRE | I40: LIVRE | K40: LIVRE | M40: LIVRE | O40: LIVRE
A42: 16h30 | C42: LIVRE | E42: LIVRE | G42: LIVRE | I42: LIVRE | K42: LIVRE | M42: LIVRE | O42: LIVRE
A44: 17h00 | C44: OCUPADO | E44: LIVRE | G44: OCUPADO | I44: OCUPADO | K44: LIVRE | M44: LIVRE | O44: LIVRE
A46: 17h30 | C46: OCUPADO | E46: OCUPADO | G46: OCUPADO | I46: OCUPADO | K46: OCUPADO | M46: LIVRE | O46: LIVRE
A48: 18h00 | C48: OCUPADO | E48: OCUPADO | G48: OCUPADO | I48: OCUPADO | K48: OCUPADO | M48: LIVRE
A50: 18h30 | C50: OCUPADO | E50: OCUPADO | G50: OCUPADO | I50: OCUPADO | K50: OCUPADO | M50: LIVRE
A52: 19h00 | C52: OCUPADO | E52: OCUPADO | G52: OCUPADO | I52: OCUPADO | K52: OCUPADO | M52: LIVRE
G53: Dur - 45' | K53: Dur - 45'
A54: 19h30 | E54: OCUPADO | I54: OCUPADO | M54: LIVRE
A56: 20h00 | E56: OCUPADO | I56: OCUPADO
A58: 20h30 | C58: LIVRE | E58: CONDICIONADO | G58: LIVRE | I58: CONDICIONADO | K58: LIVRE
A60: 21h00 | C60: LIVRE | E60: CONDICIONADO | G60: LIVRE | I60: CONDICIONADO | K60: LIVRE
A62: 21h30 | C62: LIVRE | E62: CONDICIONADO | G62: LIVRE | I62: CONDICIONADO | K62: LIVRE
A64: 22h00 | C64: LIVRE | E64: CONDICIONADO | G64: LIVRE | I64: CONDICIONADO | K64: LIVRE
A66: 22h30 | C66: LIVRE | E66: CONDICIONADO | G66: LIVRE | I66: CONDICIONADO | K66: LIVRE

Sheet Nat
A1: ESCOLA DE NATAÇÃO - Solinca Laranjeiras - Piscina
C2: SEGUNDA | E2: TERÇA | G2: QUARTA | I2: QUINTA | K2: SEXTA | M2: SÁBADO | O2: DOMINGO
M3: inserir aulas de natação
A4: 07h00 | C4: LIVRE | E4: LIVRE | G4: LIVRE | I4: LIVRE | K4: LIVRE
A6: 07h30 | C6: LIVRE | E6: LIVRE | G6: LIVRE | I6: LIVRE | K6: LIVRE
A8: 08h00 | C8: LIVRE | E8: LIVRE | G8: LIVRE | I8: LIVRE | K8: LIVRE
A10: 08h30 | C10: LIVRE | E10: LIVRE | G10: LIVRE | I10: LIVRE | K10: LIVRE
C11: Dur - 45' | G11: Dur - 45' | K11: Dur - 45'
A12: 09h00 | E12: LIVRE | I12: LIVRE | M12: LIVRE | O12: LIVRE
O13: Dur - 45'
A14: 09h15 | E14: LIVRE | I14: LIVRE | M14: LIVRE
O15: Dur - 45'
E16: LIVRE | I16: LIVRE | M16: LIVRE
A18: 09h30 | E18: LIVRE | I18: LIVRE | M18: LIVRE
E19: Dur - 45' | I19: Dur - 45' | M19: Dur - 45' | O19: Dur - 45'
A20: 10h00 | C20: LIVRE | G20: LIVRE | K20: LIVRE
A22: 10h30 | C22: LIVRE | G22: LIVRE | K22: LIVRE
A24: 11h00 | C24: LIVRE | E24: LIVRE | G24: LIVRE | I24: LIVRE | K24: LIVRE | M24: LIVRE | O24: LIVRE
A26: 11h30 | C26: LIVRE | E26: LIVRE | G26: LIVRE | I26: LIVRE | K26: LIVRE | M26: LIVRE | O26: LIVRE
E27: Dur - 45' | I27: Dur - 45'
A28: 12h00 | C28: LIVRE | G28: LIVRE | K28: LIVRE | M28: LIVRE | O28: LIVRE
O29: Dur - 45'
A30: 12h15 | C30: LIVRE | G30: LIVRE | K30: LIVRE | M30: LIVRE
A32: 12h30 | C32: LIVRE | G32: LIVRE | K32: LIVRE | M32: LIVRE
C33: Dur - 45' | E33: Dur - 45' | G33: Dur - 45' | I33: Dur - 45' | K33: Dur - 45'
A34: 13h00 | E34: HIDRO POWER | I34: HIDRO POWER | M34: LIVRE | O34: LIVRE
A36: 13h30 | M36: LIVRE | O36: LIVRE
A38: 14h00 | C38: LIVRE | E38: LIVRE | G38: LIVRE | I38: LIVRE | K38: LIVRE | M38: LIVRE | O38: LIVRE
A40: 14h30 | C40: LIVRE | E40: LIVRE | G40: LIVRE | I40: LIVRE | K40: LIVRE | M40: LIVRE | O40: LIVRE
A42: 15h00 | C42: LIVRE | E42: LIVRE | G42: LIVRE | I42: LIVRE | K42: LIVRE | M42: LIVRE | O42: LIVRE
A44: 15h30 | C44: LIVRE | E44: LIVRE | G44: LIVRE | I44: LIVRE | K44: LIVRE | M44: LIVRE | O44: LIVRE
G45: Dur - 45'
A46: 16h00 | C46: LIVRE | E46: LIVRE | G46: COLÉGIO | I46: LIVRE | K46: LIVRE | M46: LIVRE | O46: LIVRE
A48: 16h30 | C48: LIVRE | E48: LIVRE | I48: LIVRE | K48: LIVRE | M48: LIVRE | O48: LIVRE
A50: 17h00 | C50: LIVRE | E50: LIVRE | G50: LIVRE | I50: LIVRE | K50: LIVRE | M50: LIVRE | O50: LIVRE
E51: Dur - 45' | I51: Dur - 45'
A52: 17h30 | C52: LIVRE | G52: LIVRE | K52: LIVRE | M52: LIVRE | O52: LIVRE
E53: Dur - 45' | I53: Dur - 45'
C54: LIVRE | G54: LIVRE | K54: LIVRE | M54: LIVRE | O54: LIVRE
E55: Dur - 45' | I55: Dur - 45'
...

Sheet Info
F1: 2ª FEIRA | X1: 3ª FEIRA | AP1: 4ª FEIRA | BH1: 5ª FEIRA | BZ1: 6ª FEIRA | CR1: SÁBADO | DH1: DOMINGO
F2: IT | G2: SP | J2: PT | K2: VG | L2: NT | Q2: AI | R2: CF | S2: AG | X2: IT | Y2: SP | AB2: PT | AC2: VG | AD2: NT | AI2: AI | AJ2: CF | AK2: AG | AP2: IT | AQ2: SP | AT2: PT | AU2: VG | AV2: NT | BA2: AI | BB2: CF | BC2: AG | BH2: IT | BI2: SP | BL2: PT | BM2: VG | BN2: NT | BS2: AI | BT2: CF | BU2: AG | BZ2: IT | CA2: SP | CD2: PT | CE2: VG | CF2: NT | CK2: AI | CL2: CF | CM2: AG | CR2: IT | CS2: SP | CT2: PT | CU2: VG | CV2: NT | DA2: AI | DB2: CF | DC2: AG | DH2: IT | DI2: SP | DJ2: PT | DK2: VG | DL2: NT | DQ2: AI | DR2: CF | DS2: AG
L4: A | M4: B | N4: C | O4: 3 | P4: 4 | S4: E1 | T4: E2 | U4: E3 | V4: RP | W4: PS | AD4: A | AE4: B | AF4: C | AG4: 3 | AH4: 4 | AK4: E1 | AL4: E2 | AM4: E3 | AN4: RP | AV4: A | AW4: B | AX4: C | AY4: 3 | AZ4: 4 | BC4: E1 | BD4: E2 | BE4: E3 | BF4: RP | BG4: PS | BN4: A | BO4: B | BP4: C | BQ4: 3 | BR4: 4 | BU4: E1 | BV4: E2 | BW4: E3 | BX4: RP | CF4: A | CG4: B | CH4: C | CI4: 3 | CJ4: 4 | CM4: E1 | CN4: E2 | CO4: E3 | CP4: RP | CQ4: PS | CV4: A | CW4: B | CX4: C | CY4: 3 | CZ4: 4 | DC4: E1 | DD4: E2 | DE4: E3 | DF4: RP | DG4: PS | DL4: A | DM4: B | DN4: C | DO4: 3 | DP4: 4 | DS4: E1 | DT4: E2 | DU4: E3 | DV4: RP | DW4: PS
